<?xml version="1.0" ?>
<sdf version='1.6'>

  <model name='smart_grasping_sandbox'>
   
    <link name='H1_F1_base_link'>
      <pose frame=''>1.2293 0.267806 -0.014381 -1.5708 -0.762991 0</pose>
      <inertial>
        <pose frame=''>-0.000143 0.026569 0.053875 0 -0 0</pose>
        <mass>0.174652</mass>
        <inertia>
          <ixx>0.000298373</ixx>
          <ixy>-5.05752e-07</ixy>
          <ixz>1.94983e-07</ixz>
          <iyy>0.00029963</iyy>
          <iyz>2.79565e-05</iyz>
          <izz>0.00013489</izz>
        </inertia>
      </inertial>
      <collision name='H1_F1_base_link_collision'>
        <pose frame=''>0 0 0 0 -0 0</pose>
        <geometry>
          <mesh>
            <scale>1 1 1</scale>
            <uri>model://fh_desc/meshes/v2/finger_base_link_simple.dae</uri>
          </mesh>
        </geometry>
        <surface>
          <contact>
            <ode>
              <kp>1e+06</kp>
              <kd>100</kd>
              <max_vel>1</max_vel>
              <min_depth>0.002</min_depth>
            </ode>
          </contact>
          <friction>
            <ode>
              <mu>1.5</mu>
              <mu2>1.5</mu2>
              <fdir1>1 0 0</fdir1>
            </ode>
          </friction>
        </surface>
      </collision>
      <visual name='H1_F1_base_link_visual'>
        <pose frame=''>0 0 0 0 -0 0</pose>
        <geometry>
          <mesh>
            <scale>1 1 1</scale>
            <uri>model://fh_desc/meshes/v2/finger_base_link_simple.dae</uri>
          </mesh>
        </geometry>
        <material>
          <script>
            <name>Gazebo/DarkGrey</name>
            <uri>file://media/materials/scripts/gazebo.material</uri>
          </script>
        </material>
      </visual>
      <gravity>1</gravity>
      <velocity_decay/>
      <self_collide>0</self_collide>
    </link>
  
    <link name='H1_F1_link_1'>
      <pose frame=''>1.25349 0.384636 -0.039678 -1.5001 -0.762991 0</pose>
      <inertial>
        <pose frame=''>-0.000142 -0.001354 0.027761 0 -0 0</pose>
        <mass>0.082776</mass>
        <inertia>
          <ixx>4.6107e-05</ixx>
          <ixy>7.47741e-08</ixy>
          <ixz>-2.25165e-07</ixz>
          <iyy>5.27678e-05</iyy>
          <iyz>-3.64603e-07</iyz>
          <izz>2.896e-05</izz>
        </inertia>
      </inertial>
      <collision name='H1_F1_link_1_collision'>
        <pose frame=''>0 0 0 0 -0 0</pose>
        <geometry>
          <mesh>
            <scale>1 1 1</scale>
            <uri>model://fh_desc/meshes/v2/finger_prox_link_simple.dae</uri>
          </mesh>
        </geometry>
        <surface>
          <contact>
            <ode>
              <kp>1e+06</kp>
              <kd>100</kd>
              <max_vel>1</max_vel>
              <min_depth>0.002</min_depth>
            </ode>
          </contact>
          <friction>
            <ode>
              <mu>1.5</mu>
              <mu2>1.5</mu2>
              <fdir1>1 0 0</fdir1>
            </ode>
          </friction>
        </surface>
      </collision>
      <visual name='H1_F1_link_1_visual'>
        <pose frame=''>0 0 0 0 -0 0</pose>
        <geometry>
          <mesh>
            <scale>1 1 1</scale>
            <uri>model://fh_desc/meshes/v2/finger_prox_link_simple.dae</uri>
          </mesh>
        </geometry>
        <material>
          <script>
            <name>Gazebo/DarkGrey</name>
            <uri>file://media/materials/scripts/gazebo.material</uri>
          </script>
        </material>
      </visual>
      <gravity>1</gravity>
      <velocity_decay/>
      <self_collide>0</self_collide>
    </link>
    <joint name='H1_F1J2' type='revolute'>
      <child>H1_F1_link_1</child>
      <parent>H1_F1_base_link</parent>
      <axis>
        <xyz>0.722772 0 0.691086</xyz>
        <limit>
          <lower>-1.39626</lower>
          <upper>1.0472</upper>
          <effort>50</effort>
          <velocity>1</velocity>
        </limit>
        <dynamics>
          <damping>0</damping>
          <friction>0</friction>
          <spring_reference>0</spring_reference>
          <spring_stiffness>0</spring_stiffness>
        </dynamics>
        <use_parent_model_frame>1</use_parent_model_frame>
      </axis>
      <physics>
        <ode>
          <implicit_spring_damper>1</implicit_spring_damper>
          <cfm_damping>1</cfm_damping>
          <limit>
            <cfm>0</cfm>
            <erp>0.2</erp>
          </limit>
        </ode>
      </physics>
    </joint>
    <link name='H1_F1_link_2'>
      <pose frame=''>1.25056 0.444486 -0.036615 -1.50697 -0.762991 0</pose>
      <inertial>
        <pose frame=''>0.000147 -0.001929 0.020669 0 -0 0</pose>
        <mass>0.0360682</mass>
        <inertia>
          <ixx>1.45995e-05</ixx>
          <ixy>-5.02031e-08</ixy>
          <ixz>-1.65836e-07</ixz>
          <iyy>1.46464e-05</iyy>
          <iyz>-2.25421e-07</iyz>
          <izz>4.03881e-06</izz>
        </inertia>
      </inertial>
      <collision name='H1_F1_link_2_collision'>
        <pose frame=''>0 0 0 0 -0 0</pose>
        <geometry>
          <mesh>
            <scale>1 1 1</scale>
            <uri>model://fh_desc/meshes/v2/finger_dist_link_simple.dae</uri>
          </mesh>
        </geometry>
        <surface>
          <contact>
            <ode>
              <kp>1e+06</kp>
              <kd>100</kd>
              <max_vel>1</max_vel>
              <min_depth>0.002</min_depth>
            </ode>
          </contact>
          <friction>
            <ode>
              <mu>1.5</mu>
              <mu2>1.5</mu2>
              <fdir1>1 0 0</fdir1>
            </ode>
          </friction>
        </surface>
      </collision>
      <collision name='H1_F1_link_2_fixed_joint_lump__H1_F1_tip_collision_1'>
        <pose frame=''>0 0 0 0 -0 0</pose>
        <geometry>
          <mesh>
            <scale>1 1 1</scale>
            <uri>model://fh_desc/meshes/omd-d18-tip.dae</uri>
          </mesh>
        </geometry>
        <surface>
          <contact>
            <ode>
              <kp>1e+06</kp>
              <kd>100</kd>
              <max_vel>1</max_vel>
              <min_depth>0.002</min_depth>
            </ode>
          </contact>
          <friction>
            <ode>
              <mu>1.5</mu>
              <mu2>1.5</mu2>
              <fdir1>1 0 0</fdir1>
            </ode>
          </friction>
        </surface>
      </collision>
      <visual name='H1_F1_link_2_visual'>
        <pose frame=''>0 0 0 0 -0 0</pose>
        <geometry>
          <mesh>
            <scale>1 1 1</scale>
            <uri>model://fh_desc/meshes/v2/finger_dist_link_simple.dae</uri>
          </mesh>
        </geometry>
        <material>
          <script>
            <name>Gazebo/DarkGrey</name>
            <uri>file://media/materials/scripts/gazebo.material</uri>
          </script>
        </material>
      </visual>
      <visual name='H1_F1_link_2_fixed_joint_lump__H1_F1_tip_visual_1'>
        <pose frame=''>0 0 0 0 -0 0</pose>
        <geometry>
          <mesh>
            <scale>1 1 1</scale>
            <uri>model://fh_desc/meshes/omd-d18-tip.dae</uri>
          </mesh>
        </geometry>
        <material>
          <script>
            <name>Gazebo/DarkGrey</name>
            <uri>file://media/materials/scripts/gazebo.material</uri>
          </script>
        </material>
      </visual>
      <velocity_decay/>
      <gravity>1</gravity>
      <velocity_decay/>
      <self_collide>0</self_collide>
    </link>
    <joint name='H1_F1J3' type='revolute'>
      <child>H1_F1_link_2</child>
      <parent>H1_F1_link_1</parent>
      <axis>
        <xyz>0.722772 0 0.691086</xyz>
        <limit>
          <lower>-1.0472</lower>
          <upper>1.5708</upper>
          <effort>50</effort>
          <velocity>1</velocity>
        </limit>
        <dynamics>
          <damping>0</damping>
          <friction>0</friction>
          <spring_reference>0</spring_reference>
          <spring_stiffness>0</spring_stiffness>
        </dynamics>
        <use_parent_model_frame>1</use_parent_model_frame>
      </axis>
      <physics>
        <ode>
          <implicit_spring_damper>1</implicit_spring_damper>
          <cfm_damping>1</cfm_damping>
          <limit>
            <cfm>0</cfm>
            <erp>0.2</erp>
          </limit>
        </ode>
      </physics>
    </joint>
    <link name='H1_F2_base_link'>
      <pose frame=''>1.1843 0.267806 0.040619 1.5708 -0.022402 -3.14159</pose>
      <inertial>
        <pose frame=''>-0.000143 0.026569 0.053875 0 -0 0</pose>
        <mass>0.174652</mass>
        <inertia>
          <ixx>0.000298373</ixx>
          <ixy>-5.05752e-07</ixy>
          <ixz>1.94983e-07</ixz>
          <iyy>0.00029963</iyy>
          <iyz>2.79565e-05</iyz>
          <izz>0.00013489</izz>
        </inertia>
      </inertial>
      <collision name='H1_F2_base_link_collision'>
        <pose frame=''>0 0 0 0 -0 0</pose>
        <geometry>
          <mesh>
            <scale>1 1 1</scale>
            <uri>model://fh_desc/meshes/v2/finger_base_link_simple.dae</uri>
          </mesh>
        </geometry>
        <surface>
          <contact>
            <ode>
              <kp>1e+06</kp>
              <kd>100</kd>
              <max_vel>1</max_vel>
              <min_depth>0.002</min_depth>
            </ode>
          </contact>
          <friction>
            <ode>
              <mu>1.5</mu>
              <mu2>1.5</mu2>
              <fdir1>1 0 0</fdir1>
            </ode>
          </friction>
        </surface>
      </collision>
      <visual name='H1_F2_base_link_visual'>
        <pose frame=''>0 0 0 0 -0 0</pose>
        <geometry>
          <mesh>
            <scale>1 1 1</scale>
            <uri>model://fh_desc/meshes/v2/finger_base_link_simple.dae</uri>
          </mesh>
        </geometry>
        <material>
          <script>
            <name>Gazebo/DarkGrey</name>
            <uri>file://media/materials/scripts/gazebo.material</uri>
          </script>
        </material>
      </visual>
      <gravity>1</gravity>
      <velocity_decay/>
      <self_collide>0</self_collide>
    </link>

    <link name='H1_F2_link_1'>
      <pose frame=''>1.18508 0.384636 0.07561 1.64149 -0.022402 -3.14159</pose>
      <inertial>
        <pose frame=''>-0.000142 -0.001354 0.027761 0 -0 0</pose>
        <mass>0.082776</mass>
        <inertia>
          <ixx>4.6107e-05</ixx>
          <ixy>7.47741e-08</ixy>
          <ixz>-2.25165e-07</ixz>
          <iyy>5.27678e-05</iyy>
          <iyz>-3.64603e-07</iyz>
          <izz>2.896e-05</izz>
        </inertia>
      </inertial>
      <collision name='H1_F2_link_1_collision'>
        <pose frame=''>0 0 0 0 -0 0</pose>
        <geometry>
          <mesh>
            <scale>1 1 1</scale>
            <uri>model://fh_desc/meshes/v2/finger_prox_link_simple.dae</uri>
          </mesh>
        </geometry>
        <surface>
          <contact>
            <ode>
              <kp>1e+06</kp>
              <kd>100</kd>
              <max_vel>1</max_vel>
              <min_depth>0.002</min_depth>
            </ode>
          </contact>
          <friction>
            <ode>
              <mu>1.5</mu>
              <mu2>1.5</mu2>
              <fdir1>1 0 0</fdir1>
            </ode>
          </friction>
        </surface>
      </collision>
      <visual name='H1_F2_link_1_visual'>
        <pose frame=''>0 0 0 0 -0 0</pose>
        <geometry>
          <mesh>
            <scale>1 1 1</scale>
            <uri>model://fh_desc/meshes/v2/finger_prox_link_simple.dae</uri>
          </mesh>
        </geometry>
        <material>
          <script>
            <name>Gazebo/DarkGrey</name>
            <uri>file://media/materials/scripts/gazebo.material</uri>
          </script>
        </material>
      </visual>
      <gravity>1</gravity>
      <velocity_decay/>
      <self_collide>0</self_collide>
    </link>
    <joint name='H1_F2J2' type='revolute'>
      <child>H1_F2_link_1</child>
      <parent>H1_F2_base_link</parent>
      <axis>
        <xyz>-0.999749 -0 0.0224</xyz>
        <limit>
          <lower>-1.39626</lower>
          <upper>1.0472</upper>
          <effort>30</effort>
          <velocity>1</velocity>
        </limit>
        <dynamics>
          <damping>0</damping>
          <friction>0</friction>
          <spring_reference>0</spring_reference>
          <spring_stiffness>0</spring_stiffness>
        </dynamics>
        <use_parent_model_frame>1</use_parent_model_frame>
      </axis>
      <physics>
        <ode>
          <implicit_spring_damper>1</implicit_spring_damper>
          <cfm_damping>1</cfm_damping>
          <limit>
            <cfm>0</cfm>
            <erp>0.2</erp>
          </limit>
        </ode>
      </physics>
    </joint>
    <link name='H1_F2_link_2'>
      <pose frame=''>1.18499 0.444486 0.071373 1.63463 -0.022402 -3.14159</pose>
      <inertial>
        <pose frame=''>0.000147 -0.001929 0.020669 0 -0 0</pose>
        <mass>0.0360682</mass>
        <inertia>
          <ixx>1.45995e-05</ixx>
          <ixy>-5.02031e-08</ixy>
          <ixz>-1.65836e-07</ixz>
          <iyy>1.46464e-05</iyy>
          <iyz>-2.25421e-07</iyz>
          <izz>4.03881e-06</izz>
        </inertia>
      </inertial>
      <collision name='H1_F2_link_2_collision'>
        <pose frame=''>0 0 0 0 -0 0</pose>
        <geometry>
          <mesh>
            <scale>1 1 1</scale>
            <uri>model://fh_desc/meshes/v2/finger_dist_link_simple.dae</uri>
          </mesh>
        </geometry>
        <surface>
          <contact>
            <ode>
              <kp>1e+06</kp>
              <kd>100</kd>
              <max_vel>1</max_vel>
              <min_depth>0.002</min_depth>
            </ode>
          </contact>
          <friction>
            <ode>
              <mu>1.5</mu>
              <mu2>1.5</mu2>
              <fdir1>1 0 0</fdir1>
            </ode>
          </friction>
        </surface>
      </collision>
      <collision name='H1_F2_link_2_fixed_joint_lump__H1_F2_tip_collision_1'>
        <pose frame=''>0 0 0 0 -0 0</pose>
        <geometry>
          <mesh>
            <scale>1 1 1</scale>
            <uri>model://fh_desc/meshes/omd-d18-tip.dae</uri>
          </mesh>
        </geometry>
        <surface>
          <contact>
            <ode>
              <kp>1e+06</kp>
              <kd>100</kd>
              <max_vel>1</max_vel>
              <min_depth>0.002</min_depth>
            </ode>
          </contact>
          <friction>
            <ode>
              <mu>1.5</mu>
              <mu2>1.5</mu2>
              <fdir1>1 0 0</fdir1>
            </ode>
          </friction>
        </surface>
      </collision>
      <visual name='H1_F2_link_2_visual'>
        <pose frame=''>0 0 0 0 -0 0</pose>
        <geometry>
          <mesh>
            <scale>1 1 1</scale>
            <uri>model://fh_desc/meshes/v2/finger_dist_link_simple.dae</uri>
          </mesh>
        </geometry>
        <material>
          <script>
            <name>Gazebo/DarkGrey</name>
            <uri>file://media/materials/scripts/gazebo.material</uri>
          </script>
        </material>
      </visual>
      <visual name='H1_F2_link_2_fixed_joint_lump__H1_F2_tip_visual_1'>
        <pose frame=''>0 0 0 0 -0 0</pose>
        <geometry>
          <mesh>
            <scale>1 1 1</scale>
            <uri>model://fh_desc/meshes/omd-d18-tip.dae</uri>
          </mesh>
        </geometry>
        <material>
          <script>
            <name>Gazebo/DarkGrey</name>
            <uri>file://media/materials/scripts/gazebo.material</uri>
          </script>
        </material>
      </visual>
      <velocity_decay/>
      <gravity>1</gravity>
      <velocity_decay/>
      <self_collide>0</self_collide>
    </link>
    <joint name='H1_F2J3' type='revolute'>
      <child>H1_F2_link_2</child>
      <parent>H1_F2_link_1</parent>
      <axis>
        <xyz>-0.999749 -0 0.0224</xyz>
        <limit>
          <lower>-1.0472</lower>
          <upper>1.5708</upper>
          <effort>30</effort>
          <velocity>1</velocity>
        </limit>
        <dynamics>
          <damping>0</damping>
          <friction>0</friction>
          <spring_reference>0</spring_reference>
          <spring_stiffness>0</spring_stiffness>
        </dynamics>
        <use_parent_model_frame>1</use_parent_model_frame>
      </axis>
      <physics>
        <ode>
          <implicit_spring_damper>1</implicit_spring_damper>
          <cfm_damping>1</cfm_damping>
          <limit>
            <cfm>0</cfm>
            <erp>0.2</erp>
          </limit>
        </ode>
      </physics>
    </joint>
    <link name='H1_F3_base_link'>
      <pose frame=''>1.1393 0.267806 -0.014381 -1.5708 0.807795 0</pose>
      <inertial>
        <pose frame=''>-0.000143 0.026569 0.053875 0 -0 0</pose>
        <mass>0.174652</mass>
        <inertia>
          <ixx>0.000298373</ixx>
          <ixy>-5.05752e-07</ixy>
          <ixz>1.94983e-07</ixz>
          <iyy>0.00029963</iyy>
          <iyz>2.79565e-05</iyz>
          <izz>0.00013489</izz>
        </inertia>
      </inertial>
      <collision name='H1_F3_base_link_collision'>
        <pose frame=''>0 0 0 0 -0 0</pose>
        <geometry>
          <mesh>
            <scale>1 1 1</scale>
            <uri>model://fh_desc/meshes/v2/finger_base_link_simple.dae</uri>
          </mesh>
        </geometry>
        <surface>
          <contact>
            <ode>
              <kp>1e+06</kp>
              <kd>100</kd>
              <max_vel>1</max_vel>
              <min_depth>0.002</min_depth>
            </ode>
          </contact>
          <friction>
            <ode>
              <mu>1.5</mu>
              <mu2>1.5</mu2>
              <fdir1>1 0 0</fdir1>
            </ode>
          </friction>
        </surface>
      </collision>
      <visual name='H1_F3_base_link_visual'>
        <pose frame=''>0 0 0 0 -0 0</pose>
        <geometry>
          <mesh>
            <scale>1 1 1</scale>
            <uri>model://fh_desc/meshes/v2/finger_base_link_simple.dae</uri>
          </mesh>
        </geometry>
        <material>
          <script>
            <name>Gazebo/DarkGrey</name>
            <uri>file://media/materials/scripts/gazebo.material</uri>
          </script>
        </material>
      </visual>
      <gravity>1</gravity>
      <velocity_decay/>
      <self_collide>0</self_collide>
    </link>

    <link name='H1_F3_link_1'>
      <pose frame=''>1.114 0.384636 -0.038569 -1.5001 0.807795 0</pose>
      <inertial>
        <pose frame=''>-0.000142 -0.001354 0.027761 0 -0 0</pose>
        <mass>0.082776</mass>
        <inertia>
          <ixx>4.6107e-05</ixx>
          <ixy>7.47741e-08</ixy>
          <ixz>-2.25165e-07</ixz>
          <iyy>5.27678e-05</iyy>
          <iyz>-3.64603e-07</iyz>
          <izz>2.896e-05</izz>
        </inertia>
      </inertial>
      <collision name='H1_F3_link_1_collision'>
        <pose frame=''>0 0 0 0 -0 0</pose>
        <geometry>
          <mesh>
            <scale>1 1 1</scale>
            <uri>model://fh_desc/meshes/v2/finger_prox_link_simple.dae</uri>
          </mesh>
        </geometry>
        <surface>
          <contact>
            <ode>
              <kp>1e+06</kp>
              <kd>100</kd>
              <max_vel>1</max_vel>
              <min_depth>0.002</min_depth>
            </ode>
          </contact>
          <friction>
            <ode>
              <mu>1.5</mu>
              <mu2>1.5</mu2>
              <fdir1>1 0 0</fdir1>
            </ode>
          </friction>
        </surface>
      </collision>
      <visual name='H1_F3_link_1_visual'>
        <pose frame=''>0 0 0 0 -0 0</pose>
        <geometry>
          <mesh>
            <scale>1 1 1</scale>
            <uri>model://fh_desc/meshes/v2/finger_prox_link_simple.dae</uri>
          </mesh>
        </geometry>
        <material>
          <script>
            <name>Gazebo/DarkGrey</name>
            <uri>file://media/materials/scripts/gazebo.material</uri>
          </script>
        </material>
      </visual>
      <gravity>1</gravity>
      <velocity_decay/>
      <self_collide>0</self_collide>
    </link>
    <joint name='H1_F3J2' type='revolute'>
      <child>H1_F3_link_1</child>
      <parent>H1_F3_base_link</parent>
      <axis>
        <xyz>0.691094 0 -0.722765</xyz>
        <limit>
          <lower>-1.39626</lower>
          <upper>1.0472</upper>
          <effort>30</effort>
          <velocity>1</velocity>
        </limit>
        <dynamics>
          <damping>0</damping>
          <friction>0</friction>
          <spring_reference>0</spring_reference>
          <spring_stiffness>0</spring_stiffness>
        </dynamics>
        <use_parent_model_frame>1</use_parent_model_frame>
      </axis>
      <physics>
        <ode>
          <implicit_spring_damper>1</implicit_spring_damper>
          <cfm_damping>1</cfm_damping>
          <limit>
            <cfm>0</cfm>
            <erp>0.2</erp>
          </limit>
        </ode>
      </physics>
    </joint>
    <link name='H1_F3_link_2'>
      <pose frame=''>1.11707 0.444486 -0.03564 -1.50697 0.807795 0</pose>
      <inertial>
        <pose frame=''>0.000147 -0.001929 0.020669 0 -0 0</pose>
        <mass>0.0360682</mass>
        <inertia>
          <ixx>1.45995e-05</ixx>
          <ixy>-5.02031e-08</ixy>
          <ixz>-1.65836e-07</ixz>
          <iyy>1.46464e-05</iyy>
          <iyz>-2.25421e-07</iyz>
          <izz>4.03881e-06</izz>
        </inertia>
      </inertial>
      <collision name='H1_F3_link_2_collision'>
        <pose frame=''>0 0 0 0 -0 0</pose>
        <geometry>
          <mesh>
            <scale>1 1 1</scale>
            <uri>model://fh_desc/meshes/v2/finger_dist_link_simple.dae</uri>
          </mesh>
        </geometry>
        <surface>
          <contact>
            <ode>
              <kp>1e+06</kp>
              <kd>100</kd>
              <max_vel>1</max_vel>
              <min_depth>0.002</min_depth>
            </ode>
          </contact>
          <friction>
            <ode>
              <mu>1.5</mu>
              <mu2>1.5</mu2>
              <fdir1>1 0 0</fdir1>
            </ode>
          </friction>
        </surface>
      </collision>
      <collision name='H1_F3_link_2_fixed_joint_lump__H1_F3_tip_collision_1'>
        <pose frame=''>0 0 0 0 -0 0</pose>
        <geometry>
          <mesh>
            <scale>1 1 1</scale>
            <uri>model://fh_desc/meshes/omd-d18-tip.dae</uri>
          </mesh>
        </geometry>
        <surface>
          <contact>
            <ode>
              <kp>1e+06</kp>
              <kd>100</kd>
              <max_vel>1</max_vel>
              <min_depth>0.002</min_depth>
            </ode>
          </contact>
          <friction>
            <ode>
              <mu>1.5</mu>
              <mu2>1.5</mu2>
              <fdir1>1 0 0</fdir1>
            </ode>
          </friction>
        </surface>
      </collision>
      <visual name='H1_F3_link_2_visual'>
        <pose frame=''>0 0 0 0 -0 0</pose>
        <geometry>
          <mesh>
            <scale>1 1 1</scale>
            <uri>model://fh_desc/meshes/v2/finger_dist_link_simple.dae</uri>
          </mesh>
        </geometry>
        <material>
          <script>
            <name>Gazebo/DarkGrey</name>
            <uri>file://media/materials/scripts/gazebo.material</uri>
          </script>
        </material>
      </visual>
      <visual name='H1_F3_link_2_fixed_joint_lump__H1_F3_tip_visual_1'>
        <pose frame=''>0 0 0 0 -0 0</pose>
        <geometry>
          <mesh>
            <scale>1 1 1</scale>
            <uri>model://fh_desc/meshes/omd-d18-tip.dae</uri>
          </mesh>
        </geometry>
        <material>
          <script>
            <name>Gazebo/DarkGrey</name>
            <uri>file://media/materials/scripts/gazebo.material</uri>
          </script>
        </material>
      </visual>
      <velocity_decay/>
      <gravity>1</gravity>
      <velocity_decay/>
      <self_collide>0</self_collide>
    </link>
    <joint name='H1_F3J3' type='revolute'>
      <child>H1_F3_link_2</child>
      <parent>H1_F3_link_1</parent>
      <axis>
        <xyz>0.691094 0 -0.722765</xyz>
        <limit>
          <lower>-1.0472</lower>
          <upper>1.5708</upper>
          <effort>30</effort>
          <velocity>1</velocity>
        </limit>
        <dynamics>
          <damping>0</damping>
          <friction>0</friction>
          <spring_reference>0</spring_reference>
          <spring_stiffness>0</spring_stiffness>
        </dynamics>
        <use_parent_model_frame>1</use_parent_model_frame>
      </axis>
      <physics>
        <ode>
          <implicit_spring_damper>1</implicit_spring_damper>
          <cfm_damping>1</cfm_damping>
          <limit>
            <cfm>0</cfm>
            <erp>0.2</erp>
          </limit>
        </ode>
      </physics>
    </joint>



  </model>
</sdf>
